Workbook

Sheet 中证500
A1: 代码 | B1: 简称 | C1: 权重 | E1: 在池
A2: 002008.SZ | B2: 大族激光 | C2: 1.03 | E2: =ISNUMBER(MATCH(A2, 股票池!A:A, 0)) -> TRUE
A3: 002281.SZ | B3: 光迅科技 | C3: 0.937 | E3: =ISNUMBER(MATCH(A3, 股票池!A:A, 0)) -> TRUE
A4: 688347.SH | B4: 华虹宏力 | C4: 0.916 | E4: =ISNUMBER(MATCH(A4, 股票池!A:A, 0)) -> TRUE
A5: 300136.SZ | B5: 信维通信 | C5: 0.906 | E5: =ISNUMBER(MATCH(A5, 股票池!A:A, 0)) -> TRUE
A6: 300604.SZ | B6: 长川科技 | C6: 0.888 | E6: =ISNUMBER(MATCH(A6, 股票池!A:A, 0)) -> TRUE
A7: 300857.SZ | B7: 协创数据 | C7: 0.771 | E7: =ISNUMBER(MATCH(A7, 股票池!A:A, 0)) -> TRUE
A8: 002436.SZ | B8: 兴森科技 | C8: 0.624 | E8: =ISNUMBER(MATCH(A8, 股票池!A:A, 0)) -> TRUE
A9: 688120.SH | B9: 华海清科 | C9: 0.614 | E9: =ISNUMBER(MATCH(A9, 股票池!A:A, 0)) -> TRUE
A10: 300757.SZ | B10: 罗博特科 | C10: 0.61 | E10: =ISNUMBER(MATCH(A10, 股票池!A:A, 0)) -> TRUE
A11: 300058.SZ | B11: 蓝色光标 | C11: 0.569 | E11: =ISNUMBER(MATCH(A11, 股票池!A:A, 0)) -> TRUE
A12: 300395.SZ | B12: 菲利华 | C12: 0.53 | E12: =ISNUMBER(MATCH(A12, 股票池!A:A, 0)) -> TRUE
A13: 600988.SH | B13: 赤峰黄金 | C13: 0.527 | E13: =ISNUMBER(MATCH(A13, 股票池!A:A, 0)) -> TRUE
... A451: 001221.SZ | B451: 悍高集团 | C451: 0.018 | E451: =ISNUMBER(MATCH(A451, 股票池!A:A, 0)) -> TRUE
A452: 000661.SZ | B452: 长春高新 | E452: =ISNUMBER(MATCH(A452, 股票池!A:A, 0)) -> TRUE
A453: 000737.SZ | B453: 北方铜业 | E453: =ISNUMBER(MATCH(A453, 股票池!A:A, 0)) -> TRUE
A454: 000786.SZ | B454: 北新建材 | E454: =ISNUMBER(MATCH(A454, 股票池!A:A, 0)) -> TRUE
A455: 000800.SZ | B455: 一汽解放 | E455: =ISNUMBER(MATCH(A455, 股票池!A:A, 0)) -> TRUE
A456: 000983.SZ | B456: 山西焦煤 | E456: =ISNUMBER(MATCH(A456, 股票池!A:A, 0)) -> TRUE
A457: 001203.SZ | B457: 大中矿业 | E457: =ISNUMBER(MATCH(A457, 股票池!A:A, 0)) -> TRUE
A458: 001309.SZ | B458: 德明利 | E458: =ISNUMBER(MATCH(A458, 股票池!A:A, 0)) -> TRUE
A459: 001386.SZ | B459: 马可波罗 | E459: =ISNUMBER(MATCH(A459, 股票池!A:A, 0)) -> TRUE
A460: 002252.SZ | B460: 上海莱士 | E460: =ISNUMBER(MATCH(A460, 股票池!A:A, 0)) -> TRUE
A461: 002407.SZ | B461: 多氟多 | E461: =ISNUMBER(MATCH(A461, 股票池!A:A, 0)) -> TRUE
A462: 002487.SZ | B462: 大金重工 | E462: =ISNUMBER(MATCH(A462, 股票池!A:A, 0)) -> TRUE
A463: 002601.SZ | B463: 龙佰集团 | E463: =ISNUMBER(MATCH(A463, 股票池!A:A, 0)) -> TRUE
... A501: 688708.SH | B501: 佳驰科技 | E501: =ISNUMBER(MATCH(A501, 股票池!A:A, 0)) -> TRUE

Sheet 中证1000
A1: 代码 | B1: 简称 | C1: 权重 | E1: 在池
A2: 603083.SH | B2: 剑桥科技 | C2: 0.616 | E2: =ISNUMBER(MATCH(A2, 股票池!A:A, 0)) -> TRUE
A3: 300672.SZ | B3: 国科微 | C3: 0.538 | E3: =ISNUMBER(MATCH(A3, 股票池!A:A, 0)) -> TRUE
A4: 688048.SH | B4: 长光华芯 | C4: 0.524 | E4: =ISNUMBER(MATCH(A4, 股票池!A:A, 0)) -> TRUE
A5: 002428.SZ | B5: 云南锗业 | C5: 0.513 | E5: =ISNUMBER(MATCH(A5, 股票池!A:A, 0)) -> TRUE
A6: 688110.SH | B6: 东芯股份 | C6: 0.474 | E6: =ISNUMBER(MATCH(A6, 股票池!A:A, 0)) -> TRUE
A7: 000636.SZ | B7: 风华高科 | C7: 0.462 | E7: =ISNUMBER(MATCH(A7, 股票池!A:A, 0)) -> TRUE
A8: 601208.SH | B8: 东材科技 | C8: 0.438 | E8: =ISNUMBER(MATCH(A8, 股票池!A:A, 0)) -> TRUE
A9: 600330.SH | B9: 天通股份 | C9: 0.435 | E9: =ISNUMBER(MATCH(A9, 股票池!A:A, 0)) -> TRUE
A10: 002484.SZ | B10: 江海股份 | C10: 0.428 | E10: =ISNUMBER(MATCH(A10, 股票池!A:A, 0)) -> TRUE
A11: 301511.SZ | B11: 德福科技 | C11: 0.426 | E11: =ISNUMBER(MATCH(A11, 股票池!A:A, 0)) -> TRUE
A12: 601126.SH | B12: 四方股份 | C12: 0.419 | E12: =ISNUMBER(MATCH(A12, 股票池!A:A, 0)) -> TRUE
A13: 002222.SZ | B13: 福晶科技 | C13: 0.407 | E13: =ISNUMBER(MATCH(A13, 股票池!A:A, 0)) -> TRUE
... A901: 301665.SZ | B901: 泰禾股份 | C901: 0.009 | E901: =ISNUMBER(MATCH(A901, 股票池!A:A, 0)) -> TRUE
A902: 000506.SZ | B902: 招金黄金 | E902: =ISNUMBER(MATCH(A902, 股票池!A:A, 0)) -> TRUE
A903: 000534.SZ | B903: 万泽股份 | E903: =ISNUMBER(MATCH(A903, 股票池!A:A, 0)) -> TRUE
A904: 000563.SZ | B904: 陕国投A | E904: =ISNUMBER(MATCH(A904, 股票池!A:A, 0)) -> TRUE
A905: 000962.SZ | B905: 东方钽业 | E905: =ISNUMBER(MATCH(A905, 股票池!A:A, 0)) -> TRUE
A906: 000973.SZ | B906: 佛塑科技 | E906: =ISNUMBER(MATCH(A906, 股票池!A:A, 0)) -> TRUE
A907: 000998.SZ | B907: 隆平高科 | E907: =ISNUMBER(MATCH(A907, 股票池!A:A, 0)) -> TRUE
A908: 001233.SZ | B908: 海安集团 | E908: =ISNUMBER(MATCH(A908, 股票池!A:A, 0)) -> TRUE
A909: 001267.SZ | B909: 汇绿生态 | E909: =ISNUMBER(MATCH(A909, 股票池!A:A, 0)) -> TRUE
A910: 001359.SZ | B910: 平安电工 | E910: =ISNUMBER(MATCH(A910, 股票池!A:A, 0)) -> TRUE
A911: 001369.SZ | B911: 双欣材料 | E911: =ISNUMBER(MATCH(A911, 股票池!A:A, 0)) -> TRUE
A912: 001896.SZ | B912: 豫能控股 | E912: =ISNUMBER(MATCH(A912, 股票池!A:A, 0)) -> TRUE
A913: 002181.SZ | B913: 粤传媒 | E913: =ISNUMBER(MATCH(A913, 股票池!A:A, 0)) -> TRUE
... A1001: 688691.SH | B1001: 灿芯股份 | E1001: =ISNUMBER(MATCH(A1001, 股票池!A:A, 0)) -> TRUE

Sheet 沪深300
A1: 代码 | B1: 简称 | C1: 权重 | E1: 在池
A2: 300308.SZ | B2: 中际旭创 | C2: 4.7472 | E2: =ISNUMBER(MATCH(A2, 股票池!A:A, 0)) -> TRUE
A3: 300750.SZ | B3: 宁德时代 | C3: 4.2006 | E3: =ISNUMBER(MATCH(A3, 股票池!A:A, 0)) -> TRUE
A4: 600519.SH | B4: 贵州茅台 | C4: 3.1003 | E4: =ISNUMBER(MATCH(A4, 股票池!A:A, 0)) -> TRUE
A5: 300502.SZ | B5: 新易盛 | C5: 2.5548 | E5: =ISNUMBER(MATCH(A5, 股票池!A:A, 0)) -> TRUE
A6: 601318.SH | B6: 中国平安 | C6: 2.1704 | E6: =ISNUMBER(MATCH(A6, 股票池!A:A, 0)) -> TRUE
A7: 601899.SH | B7: 紫金矿业 | C7: 1.8801 | E7: =ISNUMBER(MATCH(A7, 股票池!A:A, 0)) -> TRUE
A8: 600036.SH | B8: 招商银行 | C8: 1.7877 | E8: =ISNUMBER(MATCH(A8, 股票池!A:A, 0)) -> TRUE
A9: 000333.SZ | B9: 美的集团 | C9: 1.521 | E9: =ISNUMBER(MATCH(A9, 股票池!A:A, 0)) -> TRUE
A10: 688256.SH | B10: 寒武纪 | C10: 1.4704 | E10: =ISNUMBER(MATCH(A10, 股票池!A:A, 0)) -> TRUE
A11: 002475.SZ | B11: 立讯精密 | C11: 1.3627 | E11: =ISNUMBER(MATCH(A11, 股票池!A:A, 0)) -> TRUE
A12: 600900.SH | B12: 长江电力 | C12: 1.2845 | E12: =ISNUMBER(MATCH(A12, 股票池!A:A, 0)) -> TRUE
A13: 603986.SH | B13: 兆易创新 | C13: 1.1817 | E13: =ISNUMBER(MATCH(A13, 股票池!A:A, 0)) -> TRUE
... A282: 001391.SZ | B282: 国货航 | C282: 0.0194 | E282: =ISNUMBER(MATCH(A282, 股票池!A:A, 0)) -> TRUE
A283: 000657.SZ | B283: 中钨高新 | E283: =ISNUMBER(MATCH(A283, 股票池!A:A, 0)) -> TRUE
A284: 000988.SZ | B284: 华工科技 | E284: =ISNUMBER(MATCH(A284, 股票池!A:A, 0)) -> TRUE
A285: 001280.SZ | B285: 中国铀业 | E285: =ISNUMBER(MATCH(A285, 股票池!A:A, 0)) -> TRUE
A286: 002202.SZ | B286: 金风科技 | E286: =ISNUMBER(MATCH(A286, 股票池!A:A, 0)) -> TRUE
A287: 002353.SZ | B287: 杰瑞股份 | E287: =ISNUMBER(MATCH(A287, 股票池!A:A, 0)) -> TRUE
A288: 002532.SZ | B288: 天山铝业 | E288: =ISNUMBER(MATCH(A288, 股票池!A:A, 0)) -> TRUE
A289: 002558.SZ | B289: 巨人网络 | E289: =ISNUMBER(MATCH(A289, 股票池!A:A, 0)) -> TRUE
A290: 002602.SZ | B290: 世纪华通 | E290: =ISNUMBER(MATCH(A290, 股票池!A:A, 0)) -> TRUE
A291: 002837.SZ | B291: 英维克 | E291: =ISNUMBER(MATCH(A291, 股票池!A:A, 0)) -> TRUE
A292: 300450.SZ | B292: 先导智能 | E292: =ISNUMBER(MATCH(A292, 股票池!A:A, 0)) -> TRUE
A293: 301165.SZ | B293: 锐捷网络 | E293: =ISNUMBER(MATCH(A293, 股票池!A:A, 0)) -> TRUE
A294: 301308.SZ | B294: 江波龙 | E294: =ISNUMBER(MATCH(A294, 股票池!A:A, 0)) -> TRUE
... A301: 688521.SH | B301: 芯原股份 | E301: =ISNUMBER(MATCH(A301, 股票池!A:A, 0)) -> TRUE

Sheet 研究员
A1: 代码 | B1: 简称
A2: 001965.SZ | B2: 招商公路
A3: 600233.SH | B3: 圆通速递
A4: 601872.SH | B4: 招商轮船
A5: 603885.SH | B5: 吉祥航空
A6: 603713.SH | B6: 密尔克卫
A7: 300873.SZ | B7: 海晨股份
A8: 002352.SZ | B8: 顺丰控股
A9: 600026.SH | B9: 中远海能
A10: 000099.SZ | B10: 中信海直
A11: 601000.SH | B11: 唐山港
A12: 001205.SZ | B12: 盛航股份
... A976: 301369.SZ | B976: 联动科技

Sheet 模拟盘
A1: 代码 | B1: 简称 | F1: 688382.SH | G1: =ISNUMBER(MATCH(F1, 模拟盘!A:A, 0)) -> TRUE
A2: 688630.SH | B2: 芯碁微装 | C2: 机械 | D2: =ISNUMBER(MATCH(A2, 股票池!A:A, 0)) -> TRUE
A3: 603308.SH | B3: 应流股份 | C3: 机械 | D3: =ISNUMBER(MATCH(A3, 股票池!A:A, 0)) -> TRUE
A4: 601100.SH | B4: 恒立液压 | C4: 机械 | D4: =ISNUMBER(MATCH(A4, 股票池!A:A, 0)) -> TRUE
A5: 688433.SH | B5: 华曙高科 | C5: 机械 | D5: =ISNUMBER(MATCH(A5, 股票池!A:A, 0)) -> TRUE
A6: 301338.SZ | B6: 凯格精机 | C6: 机械 | D6: =ISNUMBER(MATCH(A6, 股票池!A:A, 0)) -> TRUE
A7: 300124.SZ | B7: 汇川技术 | C7: 机械 | D7: =ISNUMBER(MATCH(A7, 股票池!A:A, 0)) -> TRUE
A8: 603268.SH | B8: 松发股份 | C8: 机械 | D8: =ISNUMBER(MATCH(A8, 股票池!A:A, 0)) -> TRUE
A9: 603011.SH | B9: 合锻智能 | C9: 机械 | D9: =ISNUMBER(MATCH(A9, 股票池!A:A, 0)) -> TRUE
A10: 000962.SZ | B10: 东方钽业 | C10: 小金属 | D10: =ISNUMBER(MATCH(A10, 股票池!A:A, 0)) -> TRUE
A11: 000688.SZ | B11: 国城矿业 | C11: 小金属 | D11: =ISNUMBER(MATCH(A11, 股票池!A:A, 0)) -> TRUE
A12: 688456.SH | B12: 有研粉材 | C12: 小金属 | D12: =ISNUMBER(MATCH(A12, 股票池!A:A, 0)) -> TRUE
A13: 600392.SH | B13: 盛和资源 | C13: 小金属 | D13: =ISNUMBER(MATCH(A13, 股票池!A:A, 0)) -> TRUE
... A96: 301319.SZ | B96: 唯特偶 | C96: 电子 | D96: =ISNUMBER(MATCH(A96, 股票池!A:A, 0)) -> TRUE
A97: 603091.SH | B97: 众鑫股份 | D97: =ISNUMBER(MATCH(A97, 股票池!A:A, 0)) -> TRUE
A98: 301061.SZ | B98: 匠心家居 | D98: =ISNUMBER(MATCH(A98, 股票池!A:A, 0)) -> TRUE
A99: 603833.SH | B99: 欧派家居 | D99: =ISNUMBER(MATCH(A99, 股票池!A:A, 0)) -> TRUE
A100: 603019.SH | B100: 中科曙光 | C100: 计算机 | D100: =ISNUMBER(MATCH(A100, 股票池!A:A, 0)) -> TRUE
A101: 300454.SZ | B101: 深信服 | C101: 计算机 | D101: =ISNUMBER(MATCH(A101, 股票池!A:A, 0)) -> TRUE
A102: 688256.SH | B102: 寒武纪 | C102: 计算机 | D102: =ISNUMBER(MATCH(A102, 股票池!A:A, 0)) -> TRUE
A103: 688343.SH | B103: 云天励飞-U | C103: 计算机 | D103: =ISNUMBER(MATCH(A103, 股票池!A:A, 0)) -> TRUE
A104: 002180.SZ | B104: 奔图科技 | C104: 计算机 | D104: =ISNUMBER(MATCH(A104, 股票池!A:A, 0)) -> TRUE
A105: 301269.SZ | B105: 华大九天 | C105: 计算机 | D105: =ISNUMBER(MATCH(A105, 股票池!A:A, 0)) -> TRUE
A106: 002990.SZ | B106: 盛视科技 | C106: 计算机 | D106: =ISNUMBER(MATCH(A106, 股票池!A:A, 0)) -> TRUE
A107: 688041.SH | B107: 海光信息 | C107: 计算机 | D107: =ISNUMBER(MATCH(A107, 股票池!A:A, 0)) -> TRUE
A108: 688111.SH | B108: 金山办公 | C108: 计算机 | D108: =ISNUMBER(MATCH(A108, 股票池!A:A, 0)) -> TRUE
A109: 002782.SZ | B109: 可立克 | C109: 计算机 | D109: =ISNUMBER(MATCH(A109, 股票池!A:A, 0)) -> TRUE
A110: 300693.SZ | B110: 盛弘股份 | C110: 新能源 | D110: =ISNUMBER(MATCH(A110, 股票池!A:A, 0)) -> TRUE
A111: 300274.SZ | B111: 阳光电源 | C111: 新能源 | D111: =ISNUMBER(MATCH(A111, 股票池!A:A, 0)) -> TRUE
... A120: 600312.SH | B120: 平高电气 | C120: 电器设备 | D120: =ISNUMBER(MATCH(A120, 股票池!A:A, 0)) -> TRUE
A121: 000807.SZ | B121: 云铝股份 | D121: =ISNUMBER(MATCH(A121, 股票池!A:A, 0)) -> TRUE
A122: 601899.SH | B122: 紫金矿业 | D122: =ISNUMBER(MATCH(A122, 股票池!A:A, 0)) -> TRUE
A123: 601600.SH | B123: 中国铝业 | D123: =ISNUMBER(MATCH(A123, 股票池!A:A, 0)) -> TRUE
A124: 000975.SZ | B124: 山金国际 | D124: =ISNUMBER(MATCH(A124, 股票池!A:A, 0)) -> TRUE
A125: 601088.SH | B125: 中国神华 | C125: 煤炭 | D125: =ISNUMBER(MATCH(A125, 股票池!A:A, 0)) -> TRUE
A126: 600188.SH | B126: 兖矿能源 | C126: 煤炭 | D126: =ISNUMBER(MATCH(A126, 股票池!A:A, 0)) -> TRUE
A127: 601225.SH | B127: 陕西煤业 | C127: 煤炭 | D127: =ISNUMBER(MATCH(A127, 股票池!A:A, 0)) -> TRUE
A128: 601898.SH | B128: 中煤能源 | C128: 煤炭 | D128: =ISNUMBER(MATCH(A128, 股票池!A:A, 0)) -> TRUE
A129: 600546.SH | B129: 山煤国际 | C129: 煤炭 | D129: =ISNUMBER(MATCH(A129, 股票池!A:A, 0)) -> TRUE
A130: 601699.SH | B130: 潞安环能 | C130: 煤炭 | D130: =ISNUMBER(MATCH(A130, 股票池!A:A, 0)) -> TRUE
...

Sheet 股票池
A1: 代码 | B1: 名称 | C1: 申万一级行业 | D1: 申万二级行业 | E1: 申万三级行业 | F1: 市值
A2: 600109.SH | B2: 国金证券 | C2: =[1]!s_info_industry_sw_2021($A2,"",1) -> 非银金融 | D2: =[1]!s_info_industry_sw_2021($A2,"",2) -> 证券Ⅱ | E2: =[1]!s_info_industry_sw_2021($A2,"",3) -> 证券Ⅲ | F2: =[1]!s_val_ev($A2,"",100000000) -> 312.7328 | H2: 688786.SH | I2: =ISNUMBER(MATCH(H2, 股票池!A:A, 0)) -> TRUE
A3: 601179.SH | B3: 中国西电 | C3: =[1]!s_info_industry_sw_2021($A3,"",1) -> 电力设备 | D3: =[1]!s_info_industry_sw_2021($A3,"",2) -> 电网设备 | E3: =[1]!s_info_industry_sw_2021($A3,"",3) -> 输变电设备 | F3: =[1]!s_val_ev($A3,"",100000000) -> 782.20965
A4: 603806.SH | B4: 福斯特 | C4: =[1]!s_info_industry_sw_2021($A4,"",1) -> 电力设备 | D4: =[1]!s_info_industry_sw_2021($A4,"",2) -> 光伏设备 | E4: =[1]!s_info_industry_sw_2021($A4,"",3) -> 光伏辅材 | F4: =[1]!s_val_ev($A4,"",100000000) -> 457.05213
A5: 688220.SH | B5: 翱捷科技-U | C5: =[1]!s_info_industry_sw_2021($A5,"",1) -> 电子 | D5: =[1]!s_info_industry_sw_2021($A5,"",2) -> 半导体 | E5: =[1]!s_info_industry_sw_2021($A5,"",3) -> 模拟芯片设计 | F5: =[1]!s_val_ev($A5,"",100000000) -> 422.94403
A6: 300857.SZ | B6: 协创数据 | C6: =[1]!s_info_industry_sw_2021($A6,"",1) -> 电子 | D6: =[1]!s_info_industry_sw_2021($A6,"",2) -> 消费电子 | E6: =[1]!s_info_industry_sw_2021($A6,"",3) -> 消费电子零部件及组装 | F6: =[1]!s_val_ev($A6,"",100000000) -> 1359.2548
A7: 603766.SH | B7: 隆鑫通用 | C7: =[1]!s_info_industry_sw_2021($A7,"",1) -> 汽车 | D7: =[1]!s_info_industry_sw_2021($A7,"",2) -> 摩托车及其他 | E7: =[1]!s_info_industry_sw_2021($A7,"",3) -> 摩托车 | F7: =[1]!s_val_ev($A7,"",100000000) -> 232.05023
A8: 603156.SH | B8: 养元饮品 | C8: =[1]!s_info_industry_sw_2021($A8,"",1) -> 食品饮料 | D8: =[1]!s_info_industry_sw_2021($A8,"",2) -> 饮料乳品 | E8: =[1]!s_info_industry_sw_2021($A8,"",3) -> 软饮料 | F8: =[1]!s_val_ev($A8,"",100000000) -> 575.69479
A9: 600909.SH | B9: 华安证券 | C9: =[1]!s_info_industry_sw_2021($A9,"",1) -> 非银金融 | D9: =[1]!s_info_industry_sw_2021($A9,"",2) -> 证券Ⅱ | E9: =[1]!s_info_industry_sw_2021($A9,"",3) -> 证券Ⅲ | F9: =[1]!s_val_ev($A9,"",100000000) -> 450.67157
A10: 002532.SZ | B10: 天山铝业 | C10: =[1]!s_info_industry_sw_2021($A10,"",1) -> 有色金属 | D10: =[1]!s_info_industry_sw_2021($A10,"",2) -> 工业金属 | E10: =[1]!s_info_industry_sw_2021($A10,"",3) -> 铝 | F10: =[1]!s_val_ev($A10,"",100000000) -> 557.76286
A11: 601231.SH | B11: 环旭电子 | C11: =[1]!s_info_industry_sw_2021($A11,"",1) -> 电子 | D11: =[1]!s_info_industry_sw_2021($A11,"",2) -> 消费电子 | E11: =[1]!s_info_industry_sw_2021($A11,"",3) -> 消费电子零部件及组装 | F11: =[1]!s_val_ev($A11,"",100000000) -> 896.08977
A12: 002436.SZ | B12: 兴森科技 | C12: =[1]!s_info_industry_sw_2021($A12,"",1) -> 电子 | D12: =[1]!s_info_industry_sw_2021($A12,"",2) -> 元件 | E12: =[1]!s_info_industry_sw_2021($A12,"",3) -> 印制电路板 | F12: =[1]!s_val_ev($A12,"",100000000) -> 884.85006
A13: 600601.SH | B13: 方正科技 | C13: =[1]!s_info_industry_sw_2021($A13,"",1) -> 电子 | D13: =[1]!s_info_industry_sw_2021($A13,"",2) -> 元件 | E13: =[1]!s_info_industry_sw_2021($A13,"",3) -> 印制电路板 | F13: =[1]!s_val_ev($A13,"",100000000) -> 615.41898
A14: 688234.SH | B14: 天岳先进 | C14: =[1]!s_info_industry_sw_2021($A14,"",1) -> 电子 | D14: =[1]!s_info_industry_sw_2021($A14,"",2) -> 半导体 | E14: =[1]!s_info_industry_sw_2021($A14,"",3) -> 半导体材料 | F14: =[1]!s_val_ev($A14,"",100000000) -> 690.2049
... A2262: 603517.SH | B2262: ST绝味 | C2262: =[1]!s_info_industry_sw_2021($A2262,"",1) -> 食品饮料 | D2262: =[1]!s_info_industry_sw_2021($A2262,"",2) -> 休闲食品 | E2262: =[1]!s_info_industry_sw_2021($A2262,"",3) -> 熟食 | F2262: =[1]!s_val_ev($A2262,"",100000000) -> 63.145402

Sheet Sheet1
A1: 指数成份代码 | B1: 日期 | D1: 代码 | E1: 名称 | F1: 在不
A2: 600109.SH | B2: 国金证券 | D2: 600109.SH | E2: 国金证券 | F2: =ISNUMBER(MATCH(A2, Sheet1!A:A, 0)) -> TRUE
A3: 601179.SH | B3: 中国西电 | D3: 601179.SH | E3: 中国西电 | F3: =ISNUMBER(MATCH(A3, Sheet1!A:A, 0)) -> TRUE
A4: 603806.SH | B4: 福斯特 | D4: 603806.SH | E4: 福斯特 | F4: =ISNUMBER(MATCH(A4, Sheet1!A:A, 0)) -> TRUE
A5: 688220.SH | B5: 翱捷科技-U | D5: 688220.SH | E5: 翱捷科技-U | F5: =ISNUMBER(MATCH(A5, Sheet1!A:A, 0)) -> TRUE
A6: 300857.SZ | B6: 协创数据 | D6: 300857.SZ | E6: 协创数据 | F6: =ISNUMBER(MATCH(A6, Sheet1!A:A, 0)) -> TRUE
A7: 603766.SH | B7: 隆鑫通用 | D7: 603766.SH | E7: 隆鑫通用 | F7: =ISNUMBER(MATCH(A7, Sheet1!A:A, 0)) -> TRUE
A8: 603156.SH | B8: 养元饮品 | D8: 603156.SH | E8: 养元饮品 | F8: =ISNUMBER(MATCH(A8, Sheet1!A:A, 0)) -> TRUE
A9: 600909.SH | B9: 华安证券 | D9: 600909.SH | E9: 华安证券 | F9: =ISNUMBER(MATCH(A9, Sheet1!A:A, 0)) -> TRUE
A10: 002532.SZ | B10: 天山铝业 | D10: 002532.SZ | E10: 天山铝业 | F10: =ISNUMBER(MATCH(A10, Sheet1!A:A, 0)) -> TRUE
A11: 601231.SH | B11: 环旭电子 | D11: 601231.SH | E11: 环旭电子 | F11: =ISNUMBER(MATCH(A11, Sheet1!A:A, 0)) -> TRUE
A12: 002436.SZ | B12: 兴森科技 | D12: 002436.SZ | E12: 兴森科技 | F12: =ISNUMBER(MATCH(A12, Sheet1!A:A, 0)) -> TRUE
A13: 600601.SH | B13: 方正科技 | D13: 600601.SH | E13: 方正科技 | F13: =ISNUMBER(MATCH(A13, Sheet1!A:A, 0)) -> TRUE
... A2068: 688808.SH | B2068: 联讯仪器 | D2068: 688808.SH | E2068: 联讯仪器 | F2068: =ISNUMBER(MATCH(A2068, Sheet1!A:A, 0)) -> TRUE
D2069: 601166.SH | E2069: 兴业银行 | F2069: =ISNUMBER(MATCH(A2069, Sheet1!A:A, 0)) -> FALSE
D2070: 300476.SZ | E2070: 胜宏科技 | F2070: =ISNUMBER(MATCH(A2070, Sheet1!A:A, 0)) -> FALSE
D2071: 601288.SH | E2071: 农业银行 | F2071: =ISNUMBER(MATCH(A2071, Sheet1!A:A, 0)) -> FALSE
D2072: 000858.SZ | E2072: 五粮液 | F2072: =ISNUMBER(MATCH(A2072, Sheet1!A:A, 0)) -> FALSE
D2073: 000651.SZ | E2073: 格力电器 | F2073: =ISNUMBER(MATCH(A2073, Sheet1!A:A, 0)) -> FALSE
D2074: 300394.SZ | E2074: 天孚通信 | F2074: =ISNUMBER(MATCH(A2074, Sheet1!A:A, 0)) -> FALSE
D2075: 601816.SH | E2075: 京沪高铁 | F2075: =ISNUMBER(MATCH(A2075, Sheet1!A:A, 0)) -> FALSE
D2076: 000063.SZ | E2076: 中兴通讯 | F2076: =ISNUMBER(MATCH(A2076, Sheet1!A:A, 0)) -> FALSE
D2077: 300408.SZ | E2077: 三环集团 | F2077: =ISNUMBER(MATCH(A2077, Sheet1!A:A, 0)) -> FALSE
D2078: 000001.SZ | E2078: 平安银行 | F2078: =ISNUMBER(MATCH(A2078, Sheet1!A:A, 0)) -> FALSE
D2079: 002142.SZ | E2079: 宁波银行 | F2079: =ISNUMBER(MATCH(A2079, Sheet1!A:A, 0)) -> FALSE
D2080: 300760.SZ | E2080: 迈瑞医疗 | F2080: =ISNUMBER(MATCH(A2080, Sheet1!A:A, 0)) -> FALSE
... D2262: 603517.SH | E2262: ST绝味 | F2262: =ISNUMBER(MATCH(A2262, Sheet1!A:A, 0)) -> FALSE
